<?xml version="1.0"?>
<robot name="humanoid_torso">
  <!-- Main body/torso -->
  <link name="torso">
    <visual>
      <origin xyz="0 0 0.5" rpy="0 0 0"/>
      <geometry>
        <box size="0.3 0.2 1.0"/>
      </geometry>
      <material name="light_gray">
        <color rgba="0.7 0.7 0.7 1"/>
      </material>
    </visual>

    <collision>
      <origin xyz="0 0 0.5" rpy="0 0 0"/>
      <geometry>
        <box size="0.3 0.2 1.0"/>
      </geometry>
    </collision>

    <inertial>
      <mass value="10.0"/>
      <origin xyz="0 0 0.5" rpy="0 0 0"/>
      <inertia ixx="0.5" ixy="0.0" ixz="0.0"
               iyy="0.6" iyz="0.0"
               izz="0.3"/>
    </inertial>
  </link>

  <!-- Neck joint -->
  <joint name="neck_joint" type="revolute">
    <parent link="torso"/>
    <child link="head"/>
    <origin xyz="0 0 1.0" rpy="0 0 0"/>
    <axis xyz="0 0 1"/>
    <limit lower="-0.5" upper="0.5" effort="20" velocity="2"/>
  </joint>

  <link name="head">
    <visual>
      <geometry>
        <sphere radius="0.1"/>
      </geometry>
      <material name="skin_color">
        <color rgba="0.8 0.6 0.4 1"/>
      </material>
    </visual>

    <collision>
      <geometry>
        <sphere radius="0.1"/>
      </geometry>
    </collision>

    <inertial>
      <mass value="2.0"/>
      <inertia ixx="0.004" ixy="0.0" ixz="0.0"
               iyy="0.004" iyz="0.0"
               izz="0.004"/>
    </inertial>
  </link>

  <!-- Left shoulder -->
  <joint name="left_shoulder_yaw" type="revolute">
    <parent link="torso"/>
    <child link="left_upper_arm"/>
    <origin xyz="0.2 0 0.6" rpy="0 0 0"/>
    <axis xyz="0 0 1"/>
    <limit lower="-1.0" upper="1.0" effort="50" velocity="2"/>
  </joint>

  <link name="left_upper_arm">
    <visual>
      <origin xyz="0 0 -0.15" rpy="1.5708 0 0"/>
      <geometry>
        <cylinder radius="0.05" length="0.3"/>
      </geometry>
      <material name="light_gray"/>
    </visual>

    <collision>
      <origin xyz="0 0 -0.15" rpy="1.5708 0 0"/>
      <geometry>
        <cylinder radius="0.05" length="0.3"/>
      </geometry>
    </collision>

    <inertial>
      <mass value="1.0"/>
      <origin xyz="0 0 -0.15" rpy="1.5708 0 0"/>
      <inertia ixx="0.005" ixy="0.0" ixz="0.0"
               iyy="0.005" iyz="0.0"
               izz="0.0001"/>
    </inertial>
  </link>

  <!-- Left elbow -->
  <joint name="left_elbow" type="revolute">
    <parent link="left_upper_arm"/>
    <child link="left_forearm"/>
    <origin xyz="0 0 -0.3" rpy="0 0 0"/>
    <axis xyz="0 1 0"/>
    <limit lower="-2.0" upper="0.0" effort="30" velocity="2"/>
  </joint>

  <link name="left_forearm">
    <visual>
      <origin xyz="0 0 -0.125" rpy="1.5708 0 0"/>
      <geometry>
        <cylinder radius="0.04" length="0.25"/>
      </geometry>
      <material name="light_gray"/>
    </visual>

    <collision>
      <origin xyz="0 0 -0.125" rpy="1.5708 0 0"/>
      <geometry>
        <cylinder radius="0.04" length="0.25"/>
      </geometry>
    </collision>

    <inertial>
      <mass value="0.8"/>
      <origin xyz="0 0 -0.125" rpy="1.5708 0 0"/>
      <inertia ixx="0.003" ixy="0.0" ixz="0.0"
               iyy="0.003" iyz="0.0"
               izz="0.0001"/>
    </inertial>
  </link>

  <!-- Right shoulder (mirrored) -->
  <joint name="right_shoulder_yaw" type="revolute">
    <parent link="torso"/>
    <child link="right_upper_arm"/>
    <origin xyz="-0.2 0 0.6" rpy="0 0 0"/>
    <axis xyz="0 0 1"/>
    <limit lower="-1.0" upper="1.0" effort="50" velocity="2"/>
  </joint>

  <link name="right_upper_arm">
    <visual>
      <origin xyz="0 0 -0.15" rpy="1.5708 0 0"/>
      <geometry>
        <cylinder radius="0.05" length="0.3"/>
      </geometry>
      <material name="light_gray"/>
    </visual>

    <collision>
      <origin xyz="0 0 -0.15" rpy="1.5708 0 0"/>
      <geometry>
        <cylinder radius="0.05" length="0.3"/>
      </geometry>
    </collision>

    <inertial>
      <mass value="1.0"/>
      <origin xyz="0 0 -0.15" rpy="1.5708 0 0"/>
      <inertia ixx="0.005" ixy="0.0" ixz="0.0"
               iyy="0.005" iyz="0.0"
               izz="0.0001"/>
    </inertial>
  </link>

  <!-- Right elbow -->
  <joint name="right_elbow" type="revolute">
    <parent link="right_upper_arm"/>
    <child link="right_forearm"/>
    <origin xyz="0 0 -0.3" rpy="0 0 0"/>
    <axis xyz="0 1 0"/>
    <limit lower="-2.0" upper="0.0" effort="30" velocity="2"/>
  </joint>

  <link name="right_forearm">
    <visual>
      <origin xyz="0 0 -0.125" rpy="1.5708 0 0"/>
      <geometry>
        <cylinder radius="0.04" length="0.25"/>
      </geometry>
      <material name="light_gray"/>
    </visual>

    <collision>
      <origin xyz="0 0 -0.125" rpy="1.5708 0 0"/>
      <geometry>
        <cylinder radius="0.04" length="0.25"/>
      </geometry>
    </collision>

    <inertial>
      <mass value="0.8"/>
      <origin xyz="0 0 -0.125" rpy="1.5708 0 0"/>
      <inertia ixx="0.003" ixy="0.0" ixz="0.0"
               iyy="0.003" iyz="0.0"
               izz="0.0001"/>
    </inertial>
  </link>
</robot>